Workbook

Sheet DETAILED-SP
B2: MGL Basic Reports From New Software
B4: SP NAME | C4: BHOPAL | D4: FM WK NO | E4: 1 | F4: TO WEEK NO | G4: 5 | I4: FM MON | J4: 43101 | K4: TO MON | L4: 43101 | M4: Product | N4: Sea Export
B6: MGL REF | C6: UNIT | D6: NOS | E6: FREIGHT | F6: INLAND | G6: OTHERS | H6: GROSS | I6: FREIGHT | J6: FRT COMM | K6: INLAND | L6: OTHERS | M6: GROSS | N6: GROSS | O6: AVG REV | P6: AVG COST | Q6: AVG MAR | R6: G P RATIO
E7: REVENUE | F7: REVENUE | G7: REVENUE | H7: SALES | I7: COST | J7: 2.5% - [if Y] | K7: COST | L7: COST | M7: COST | N7: PROFIT | O7: PER UNIT | P7: PER UNIT | Q7: PER UNIT | R7: IN %
B8: BH180001 | C8: 20 | D8: 1 | E8: 2000 | F8: 1000 | G8: 200 | H8: =SUM(E8:G8) -> 3200 | I8: =E8*0.8 -> 1600 | J8: =I8*0.025*-1 -> -40 | K8: =F8*0.7 -> 700 | L8: =G8*0.5 -> 100 | M8: =SUM(I8:L8) -> 2360 | N8: =H8-M8 -> 840 | O8: =H8/D8 -> 3200 | P8: =M8/D8 -> 2360 | Q8: =N8/D8 -> 840 | R8: =Q8/H8 -> 0.2625
B9: BH180002 | C9: 40 | D9: 1 | E9: 2000 | F9: 1000 | G9: 200 | H9: =SUM(E9:G9) -> 3200 | I9: =E9*0.8 -> 1600 | J9: =I9*0.025*-1 -> -40 | K9: =F9*0.7 -> 700 | L9: =G9*0.5 -> 100 | M9: =SUM(I9:L9) -> 2360 | N9: =H9-M9 -> 840 | O9: =H9/D9 -> 3200 | P9: =M9/D9 -> 2360 | Q9: =N9/D9 -> 840 | R9: =Q9/H9 -> 0.2625
B10: BH180003 | C10: 40 | D10: 1 | E10: 2000 | F10: 1000 | G10: 200 | H10: =SUM(E10:G10) -> 3200 | I10: =E10*0.8 -> 1600 | J10: =I10*0.025*-1 -> -40 | K10: =F10*0.7 -> 700 | L10: =G10*0.5 -> 100 | M10: =SUM(I10:L10) -> 2360 | N10: =H10-M10 -> 840 | O10: =H10/D10 -> 3200 | P10: =M10/D10 -> 2360 | Q10: =N10/D10 -> 840 | R10: =Q10/H10 -> 0.2625
B11: BH180004 | C11: 20 | D11: 1 | E11: 2000 | F11: 1000 | G11: 200 | H11: =SUM(E11:G11) -> 3200 | I11: =E11*0.8 -> 1600 | J11: =I11*0.025*-1 -> -40 | K11: =F11*0.7 -> 700 | L11: =G11*0.5 -> 100 | M11: =SUM(I11:L11) -> 2360 | N11: =H11-M11 -> 840 | O11: =H11/D11 -> 3200 | P11: =M11/D11 -> 2360 | Q11: =N11/D11 -> 840 | R11: =Q11/H11 -> 0.2625
B12: BH180005 | C12: 20 | D12: 2 | E12: 4000 | F12: 2000 | G12: 400 | H12: =SUM(E12:G12) -> 6400 | I12: =E12*0.8 -> 3200 | J12: =I12*0.025*-1 -> -80 | K12: =F12*0.7 -> 1400 | L12: =G12*0.5 -> 200 | M12: =SUM(I12:L12) -> 4720 | N12: =H12-M12 -> 1680 | O12: =H12/D12 -> 3200 | P12: =M12/D12 -> 2360 | Q12: =N12/D12 -> 840 | R12: =Q12/H12 -> 0.13125
B13: BH180006 | C13: 40 | D13: 2 | E13: 2000 | F13: 1000 | G13: 200 | H13: =SUM(E13:G13) -> 3200 | I13: =E13*0.8 -> 1600 | J13: =I13*0.025*-1 -> -40 | K13: =F13*0.7 -> 700 | L13: =G13*0.5 -> 100 | M13: =SUM(I13:L13) -> 2360 | N13: =H13-M13 -> 840 | O13: =H13/D13 -> 1600 | P13: =M13/D13 -> 1180 | Q13: =N13/D13 -> 420 | R13: =Q13/H13 -> 0.13125
B14: BH180007 | C14: 40 | D14: 1 | E14: 2000 | F14: 1000 | G14: 200 | H14: =SUM(E14:G14) -> 3200 | I14: =E14*0.8 -> 1600 | J14: =I14*0.025*-1 -> -40 | K14: =F14*0.7 -> 700 | L14: =G14*0.5 -> 100 | M14: =SUM(I14:L14) -> 2360 | N14: =H14-M14 -> 840 | O14: =H14/D14 -> 3200 | P14: =M14/D14 -> 2360 | Q14: =N14/D14 -> 840 | R14: =Q14/H14 -> 0.2625
B15: BH180008 | C15: 20 | D15: 1 | E15: 2000 | F15: 1000 | G15: 200 | H15: =SUM(E15:G15) -> 3200 | I15: =E15*0.8 -> 1600 | J15: =I15*0.025*-1 -> -40 | K15: =F15*0.7 -> 700 | L15: =G15*0.5 -> 100 | M15: =SUM(I15:L15) -> 2360 | N15: =H15-M15 -> 840 | O15: =H15/D15 -> 3200 | P15: =M15/D15 -> 2360 | Q15: =N15/D15 -> 840 | R15: =Q15/H15 -> 0.2625
B16: BH180009 | C16: 20 | D16: 1 | E16: 2000 | F16: 1000 | G16: 200 | H16: =SUM(E16:G16) -> 3200 | I16: =E16*0.8 -> 1600 | J16: =I16*0.025*-1 -> -40 | K16: =F16*0.7 -> 700 | L16: =G16*0.5 -> 100 | M16: =SUM(I16:L16) -> 2360 | N16: =H16-M16 -> 840 | O16: =H16/D16 -> 3200 | P16: =M16/D16 -> 2360 | Q16: =N16/D16 -> 840 | R16: =Q16/H16 -> 0.2625
B17: BH180010 | C17: 40 | D17: 4 | E17: 10000 | F17: 4000 | G17: 1000 | H17: =SUM(E17:G17) -> 15000 | I17: =E17*0.8 -> 8000 | J17: =I17*0.025*-1 -> -200 | K17: =F17*0.7 -> 2800 | L17: =G17*0.5 -> 500 | M17: =SUM(I17:L17) -> 11100 | N17: =H17-M17 -> 3900 | O17: =H17/D17 -> 3750 | P17: =M17/D17 -> 2775 | Q17: =N17/D17 -> 975 | R17: =Q17/H17 -> 0.065
B18: BH180011 | C18: 40 | D18: 1 | E18: 2000 | F18: 1000 | G18: 200 | H18: =SUM(E18:G18) -> 3200 | I18: =E18*0.8 -> 1600 | J18: =I18*0.025*-1 -> -40 | K18: =F18*0.7 -> 700 | L18: =G18*0.5 -> 100 | M18: =SUM(I18:L18) -> 2360 | N18: =H18-M18 -> 840 | O18: =H18/D18 -> 3200 | P18: =M18/D18 -> 2360 | Q18: =N18/D18 -> 840 | R18: =Q18/H18 -> 0.2625
B19: BH180012 | C19: 20 | D19: 1 | E19: 2000 | F19: 1000 | G19: 200 | H19: =SUM(E19:G19) -> 3200 | I19: =E19*0.8 -> 1600 | J19: =I19*0.025*-1 -> -40 | K19: =F19*0.7 -> 700 | L19: =G19*0.5 -> 100 | M19: =SUM(I19:L19) -> 2360 | N19: =H19-M19 -> 840 | O19: =H19/D19 -> 3200 | P19: =M19/D19 -> 2360 | Q19: =N19/D19 -> 840 | R19: =Q19/H19 -> 0.2625
... B21: BH180014 | C21: 20 | D21: 1 | E21: 2000 | F21: 1000 | G21: 200 | H21: =SUM(E21:G21) -> 3200 | I21: =E21*0.8 -> 1600 | J21: =I21*0.025*-1 -> -40 | K21: =F21*0.7 -> 700 | L21: =G21*0.5 -> 100 | M21: =SUM(I21:L21) -> 2360 | N21: =H21-M21 -> 840 | O21: =H21/D21 -> 3200 | P21: =M21/D21 -> 2360 | Q21: =N21/D21 -> 840 | R21: =Q21/H21 -> 0.2625
B22: TOTALS | C22: =C4 -> BHOPAL | D22: =SUM(D8:D21) -> 19 | E22: =SUM(E8:E21) -> 38000 | F22: =SUM(F8:F21) -> 18000 | G22: =SUM(G8:G21) -> 3800 | H22: =SUM(H8:H21) -> 59800 | I22: =SUM(I8:I21) -> 30400 | J22: =SUM(J8:J21) -> -760 | K22: =SUM(K8:K21) -> 12600 | ... N22: =SUM(N8:N21) -> 15660 | O22: =H22/D22 -> 3147.3684 | P22: =M22/D22 -> 2323.1579 | Q22: =N22/D22 -> 824.21053 | R22: =Q22/O22 -> 0.26187291
B25: MGL Basic Reports From New Software
B27: SP NAME | C27: DELHI | D27: FM WK NO | E27: 1 | F27: TO WEEK NO | G27: 5 | I27: FM MON | J27: 43101 | K27: TO MON | L27: 43101 | M27: Product | N27: Sea Export
B29: MGL REF | C29: UNIT | D29: NOS | E29: FREIGHT | F29: INLAND | G29: OTHERS | H29: GROSS | I29: FREIGHT | J29: FRT COMM | K29: INLAND | L29: OTHERS | M29: GROSS | N29: GROSS | O29: AVG REV | P29: AVG COST | Q29: AVG MAR | R29: G P RATIO
E30: REVENUE | F30: REVENUE | G30: REVENUE | H30: SALES | I30: COST | J30: 2.5% - [if Y] | K30: COST | L30: COST | M30: COST | N30: PROFIT | O30: PER UNIT | P30: PER UNIT | Q30: PER UNIT | R30: IN %
B31: DE180001 | C31: 20 | D31: 1 | E31: 2000 | F31: 1000 | G31: 200 | H31: =SUM(E31:G31) -> 3200 | I31: =E31*0.8 -> 1600 | J31: =I31*0.025*-1 -> -40 | K31: =F31*0.7 -> 700 | L31: =G31*0.5 -> 100 | M31: =SUM(I31:L31) -> 2360 | N31: =H31-M31 -> 840 | O31: =H31/D31 -> 3200 | P31: =M31/D31 -> 2360 | Q31: =N31/D31 -> 840 | R31: =Q31/H31 -> 0.2625
B32: DE180002 | C32: 40 | D32: 1 | E32: 2000 | F32: 1000 | G32: 200 | H32: =SUM(E32:G32) -> 3200 | I32: =E32*0.8 -> 1600 | J32: =I32*0.025*-1 -> -40 | K32: =F32*0.7 -> 700 | L32: =G32*0.5 -> 100 | M32: =SUM(I32:L32) -> 2360 | N32: =H32-M32 -> 840 | O32: =H32/D32 -> 3200 | P32: =M32/D32 -> 2360 | Q32: =N32/D32 -> 840 | R32: =Q32/H32 -> 0.2625
B33: DE180003 | C33: 40 | D33: 1 | E33: 2000 | F33: 1000 | G33: 200 | H33: =SUM(E33:G33) -> 3200 | I33: =E33*0.8 -> 1600 | J33: =I33*0.025*-1 -> -40 | K33: =F33*0.7 -> 700 | L33: =G33*0.5 -> 100 | M33: =SUM(I33:L33) -> 2360 | N33: =H33-M33 -> 840 | O33: =H33/D33 -> 3200 | P33: =M33/D33 -> 2360 | Q33: =N33/D33 -> 840 | R33: =Q33/H33 -> 0.2625
B34: DE180004 | C34: 20 | D34: 1 | E34: 2000 | F34: 1000 | G34: 200 | H34: =SUM(E34:G34) -> 3200 | I34: =E34*0.8 -> 1600 | J34: =I34*0.025*-1 -> -40 | K34: =F34*0.7 -> 700 | L34: =G34*0.5 -> 100 | M34: =SUM(I34:L34) -> 2360 | N34: =H34-M34 -> 840 | O34: =H34/D34 -> 3200 | P34: =M34/D34 -> 2360 | Q34: =N34/D34 -> 840 | R34: =Q34/H34 -> 0.2625
B35: DE180005 | C35: 20 | D35: 2 | E35: 4000 | F35: 2000 | G35: 400 | H35: =SUM(E35:G35) -> 6400 | I35: =E35*0.8 -> 3200 | J35: =I35*0.025*-1 -> -80 | K35: =F35*0.7 -> 1400 | L35: =G35*0.5 -> 200 | M35: =SUM(I35:L35) -> 4720 | N35: =H35-M35 -> 1680 | O35: =H35/D35 -> 3200 | P35: =M35/D35 -> 2360 | Q35: =N35/D35 -> 840 | R35: =Q35/H35 -> 0.13125
B36: DE180006 | C36: 40 | D36: 2 | E36: 2000 | F36: 1000 | G36: 200 | H36: =SUM(E36:G36) -> 3200 | I36: =E36*0.8 -> 1600 | J36: =I36*0.025*-1 -> -40 | K36: =F36*0.7 -> 700 | L36: =G36*0.5 -> 100 | M36: =SUM(I36:L36) -> 2360 | N36: =H36-M36 -> 840 | O36: =H36/D36 -> 1600 | P36: =M36/D36 -> 1180 | Q36: =N36/D36 -> 420 | R36: =Q36/H36 -> 0.13125
B37: DE180007 | C37: 40 | D37: 1 | E37: 2000 | F37: 1000 | G37: 200 | H37: =SUM(E37:G37) -> 3200 | I37: =E37*0.8 -> 1600 | J37: =I37*0.025*-1 -> -40 | K37: =F37*0.7 -> 700 | L37: =G37*0.5 -> 100 | M37: =SUM(I37:L37) -> 2360 | N37: =H37-M37 -> 840 | O37: =H37/D37 -> 3200 | P37: =M37/D37 -> 2360 | Q37: =N37/D37 -> 840 | R37: =Q37/H37 -> 0.2625
B38: DE180008 | C38: 20 | D38: 1 | E38: 2000 | F38: 1000 | G38: 200 | H38: =SUM(E38:G38) -> 3200 | I38: =E38*0.8 -> 1600 | J38: =I38*0.025*-1 -> -40 | K38: =F38*0.7 -> 700 | L38: =G38*0.5 -> 100 | M38: =SUM(I38:L38) -> 2360 | N38: =H38-M38 -> 840 | O38: =H38/D38 -> 3200 | P38: =M38/D38 -> 2360 | Q38: =N38/D38 -> 840 | R38: =Q38/H38 -> 0.2625
B39: DE180009 | C39: 20 | D39: 1 | E39: 2000 | F39: 1000 | G39: 200 | H39: =SUM(E39:G39) -> 3200 | I39: =E39*0.8 -> 1600 | J39: =I39*0.025*-1 -> -40 | K39: =F39*0.7 -> 700 | L39: =G39*0.5 -> 100 | M39: =SUM(I39:L39) -> 2360 | N39: =H39-M39 -> 840 | O39: =H39/D39 -> 3200 | P39: =M39/D39 -> 2360 | Q39: =N39/D39 -> 840 | R39: =Q39/H39 -> 0.2625
B40: DE180010 | C40: 40 | D40: 4 | E40: 10000 | F40: 4000 | G40: 1000 | H40: =SUM(E40:G40) -> 15000 | I40: =E40*0.8 -> 8000 | J40: =I40*0.025*-1 -> -200 | K40: =F40*0.7 -> 2800 | L40: =G40*0.5 -> 500 | M40: =SUM(I40:L40) -> 11100 | N40: =H40-M40 -> 3900 | O40: =H40/D40 -> 3750 | P40: =M40/D40 -> 2775 | Q40: =N40/D40 -> 975 | R40: =Q40/H40 -> 0.065
B41: DE180011 | C41: 40 | D41: 1 | E41: 2000 | F41: 1000 | G41: 200 | H41: =SUM(E41:G41) -> 3200 | I41: =E41*0.8 -> 1600 | J41: =I41*0.025*-1 -> -40 | K41: =F41*0.7 -> 700 | L41: =G41*0.5 -> 100 | M41: =SUM(I41:L41) -> 2360 | N41: =H41-M41 -> 840 | O41: =H41/D41 -> 3200 | P41: =M41/D41 -> 2360 | Q41: =N41/D41 -> 840 | R41: =Q41/H41 -> 0.2625
B42: DE180012 | C42: 20 | D42: 1 | E42: 2000 | F42: 1000 | G42: 200 | H42: =SUM(E42:G42) -> 3200 | I42: =E42*0.8 -> 1600 | J42: =I42*0.025*-1 -> -40 | K42: =F42*0.7 -> 700 | L42: =G42*0.5 -> 100 | M42: =SUM(I42:L42) -> 2360 | N42: =H42-M42 -> 840 | O42: =H42/D42 -> 3200 | P42: =M42/D42 -> 2360 | Q42: =N42/D42 -> 840 | R42: =Q42/H42 -> 0.2625
... B44: DE180014 | C44: 20 | D44: 1 | E44: 2000 | F44: 1000 | G44: 200 | H44: =SUM(E44:G44) -> 3200 | I44: =E44*0.8 -> 1600 | J44: =I44*0.025*-1 -> -40 | K44: =F44*0.7 -> 700 | L44: =G44*0.5 -> 100 | M44: =SUM(I44:L44) -> 2360 | N44: =H44-M44 -> 840 | O44: =H44/D44 -> 3200 | P44: =M44/D44 -> 2360 | Q44: =N44/D44 -> 840 | R44: =Q44/H44 -> 0.2625
B45: TOTALS | C45: =C27 -> DELHI | D45: =SUM(D31:D44) -> 19 | E45: =SUM(E31:E44) -> 38000 | F45: =SUM(F31:F44) -> 18000 | G45: =SUM(G31:G44) -> 3800 | H45: =SUM(H31:H44) -> 59800 | I45: =SUM(I31:I44) -> 30400 | J45: =SUM(J31:J44) -> -760 | K45: =SUM(K31:K44) -> 12600 | ... N45: =SUM(N31:N44) -> 15660 | O45: =H45/D45 -> 3147.3684 | P45: =M45/D45 -> 2323.1579 | Q45: =N45/D45 -> 824.21053 | R45: =Q45/O45 -> 0.26187291
B48: SP NAME | C48: BOM | D48: FM WK NO | E48: 1 | F48: TO WEEK NO | G48: 5 | I48: FM MON | J48: 43101 | K48: TO MON | L48: 43101 | M48: Product | N48: Sea Export
B50: MGL REF | C50: UNIT | D50: NOS | E50: FREIGHT | F50: INLAND | G50: OTHERS | H50: GROSS | I50: FREIGHT | J50: FRT COMM | K50: INLAND | L50: OTHERS | M50: GROSS | N50: GROSS | O50: AVG REV | P50: AVG COST | Q50: AVG MAR | R50: G P RATIO
E51: REVENUE | F51: REVENUE | G51: REVENUE | H51: SALES | I51: COST | J51: 2.5% - [if Y] | K51: COST | L51: COST | M51: COST | N51: PROFIT | O51: PER UNIT | P51: PER UNIT | Q51: PER UNIT | R51: IN %
B52: MU180001 | C52: 20 | D52: 1 | E52: 2000 | F52: 1000 | G52: 200 | H52: =SUM(E52:G52) -> 3200 | I52: =E52*0.8 -> 1600 | J52: =I52*0.025*-1 -> -40 | K52: =F52*0.7 -> 700 | L52: =G52*0.5 -> 100 | M52: =SUM(I52:L52) -> 2360 | N52: =H52-M52 -> 840 | O52: =H52/D52 -> 3200 | P52: =M52/D52 -> 2360 | Q52: =N52/D52 -> 840 | R52: =Q52/H52 -> 0.2625
...

Sheet IMP-FIELDS-CODES
B2: MGL SOFTWARE DEVELOPMENT
B3: ESSENTIAL FILEDS FM ENQUIRY LEVEL WHICH WILL GET TRANSFERRED TO QUOTATION, THEN BOOKING, THEN INVOICE
B4: THE SAME TO BE FOR ISSUANCE OF A CREDIT NOTE
B6: IMPORTANT FIELDS [besides various others already advised by Chaks and Hamid]. There could be duplication.
F8: FEE % | G8: FEE%
B9: 1 | C9: SP NAME | E9: in abbreviated form ie BH for bhopal and MU for Mumbai | F9: MAIN SP | G9: OTH SP
B10: 2 | C10: BUSINESS TYPE | E10: MN = MGL NOMINATED | F10: 0.2 | G10: 0
B11: 3 | E11: SN=SP GENERATED/NOMINATED | F11: 0.4 | G11: 0
B12: 4 | E12: MS=OLD MGL BUT SECURED BY SP | F12: 0.3 | G12: 0.3
B13: 5 | E13: RN=REFERRED BY MGL NOMIDATED CUSTOMER | F13: 0.3 | G13: 0.3
B14: 6 | E14: SH = SP NOMINATED AND HANDLED BY OTHER SP | F14: 0.3 | G14: 0.1
B15: 7
B16: 8
B17: 9
B18: 10
B20: 11 | C20: HS | E20: HANDLING SP
F22: COMMON SALES AND COST OF SALES CODES
B23: MAIN TYPES OF BUSINESS | F23: [FULL LIST WILL BE PROVIDED BY IP/HH/KC]
C24: SEA EXPORT | E24: BY RESPECTIVE SP
C25: SEA IMPORT | E25: BY RESPECTIVE SP | F25: NAME | G25: REV CODE | H25: COST CODE
C26: SEA CROSS TRADE | E26: BY RESPECTIVE SP | F26: Ocean Freight | G26: 201 | H26: =G26-100 -> 101
C27: SEA TRANSHIPMENT | E27: BY RESPECTIVE SP | F27: Air Freight | G27: =G26+1 -> 202 | H27: =G27-100 -> 102
E28: BY RESPECTIVE SP | F28: T/S Freight | G28: =G27+1 -> 203 | H28: =G28-100 -> 103
C29: AIR EXPORT | E29: BY RESPECTIVE SP | F29: THC Origin | G29: =G28+1 -> 204 | H29: =G29-100 -> 104
C30: AIR IMPORT | E30: BY RESPECTIVE SP | F30: THC Destination | G30: =G29+1 -> 205 | H30: =G30-100 -> 105
C31: AIR CROSS TRADE | E31: BY RESPECTIVE SP | F31: Handling IN | G31: =G30+1 -> 206 | H31: =G31-100 -> 106
C32: AIR HANDLING | E32: BY RESPECTIVE SP | F32: Handling OUT | G32: =G31+1 -> 207 | H32: =G32-100 -> 107
E33: BY RESPECTIVE SP | F33: Sealing | G33: =G32+1 -> 208 | H33: =G33-100 -> 108
C34: WAREHOUSING | E34: BY RESPECTIVE SP | F34: BL Fee | G34: =G33+1 -> 209 | H34: =G34-100 -> 109
C35: TRUCKING | E35: BY RESPECTIVE SP | F35: Attestation | G35: =G34+1 -> 210 | H35: =G35-100 -> 110
C36: CLEARING | E36: BY RESPECTIVE SP | F36: Legalisation | G36: =G35+1 -> 211 | H36: =G36-100 -> 111
C37: FORWARDING | E37: BY RESPECTIVE SP | F37: Documentation | G37: =G36+1 -> 212 | H37: =G37-100 -> 112
E38: BY RESPECTIVE SP | F38: Origin Agents fee | G38: =G37+1 -> 213 | H38: =G38-100 -> 113
F39: Destination Agents Fee | G39: =G38+1 -> 214 | H39: =G39-100 -> 114
F40: Trucking-Origin | G40: =G39+1 -> 215 | H40: =G40-100 -> 115
F41: Trucking-Destination | G41: =G40+1 -> 216 | H41: =G41-100 -> 116
F42: Origin-Loading | G42: =G41+1 -> 217 | H42: =G42-100 -> 117
F43: Destination-Loading | G43: =G42+1 -> 218 | H43: =G43-100 -> 118
F44: Labour | G44: =G43+1 -> 219 | H44: =G44-100 -> 119
F45: Crane Hire | G45: =G44+1 -> 220 | H45: =G45-100 -> 120
...

Sheet INVOICEAND EXPECTED COSTS
B2: A TYPICAL DETAIL QUOTATION [ASSUMED ALL SALES AND COST ELEMENTS]…..
C3: INQ NO | D3: QUOTE NO | E3: MGL REF NO | G3: OUT QUOTED | H3: Cost Quoted | I3: Supplier
C4: 123456 | D4: 7891011 | E4: BH18SFE001 | G4: Amount | H4: by Suppliers | I4: Name
G5: TO BILL | H5: Expected
B6: NAME | C6: REV CODE | D6: COST CODE
B7: Ocean Freight | C7: 201 | D7: =C7-100 -> 101 | G7: 5000 | H7: =G7*0.75 -> 3750 | I7: Mr. Fakir 01 | K7: the customers and suppliers name should be there in the system
B8: Air Freight | C8: =C7+1 -> 202 | D8: =C8-100 -> 102 | G8: =G7-100 -> 4900 | H8: =G8*0.75 -> 3675 | I8: Mr. Fakir 02 | K8: the expected cost to be transferred to cost of sales account.
B9: T/S Freight | C9: =C8+1 -> 203 | D9: =C9-100 -> 103 | G9: =G8-100 -> 4800 | H9: =G9*0.75 -> 3600 | I9: Mr. Fakir 03 | K9: once actual vendor invoives will come it will be keyed off against expected cost in Quick Books
B10: THC Origin | C10: =C9+1 -> 204 | D10: =C10-100 -> 104 | G10: =G9-100 -> 4700 | H10: =G10*0.75 -> 3525 | I10: Mr. Fakir 04
B11: THC Destination | C11: =C10+1 -> 205 | D11: =C11-100 -> 105 | G11: =G10-100 -> 4600 | H11: =G11*0.75 -> 3450 | I11: Mr. Fakir 05
B12: Handling IN | C12: =C11+1 -> 206 | D12: =C12-100 -> 106 | G12: =G11-100 -> 4500 | H12: =G12*0.75 -> 3375 | I12: Mr. Fakir 06
B13: Handling OUT | C13: =C12+1 -> 207 | D13: =C13-100 -> 107 | G13: =G12-100 -> 4400 | H13: =G13*0.75 -> 3300 | I13: Mr. Fakir 07
B14: Sealing | C14: =C13+1 -> 208 | D14: =C14-100 -> 108 | G14: =G13-100 -> 4300 | H14: =G14*0.75 -> 3225 | I14: Mr. Fakir 08
B15: BL Fee | C15: =C14+1 -> 209 | D15: =C15-100 -> 109 | G15: =G14-100 -> 4200 | H15: =G15*0.75 -> 3150 | I15: Mr. Fakir 09
B16: Attestation | C16: =C15+1 -> 210 | D16: =C16-100 -> 110 | G16: =G15-100 -> 4100 | H16: =G16*0.75 -> 3075 | I16: Mr. Fakir 10
B17: Legalisation | C17: =C16+1 -> 211 | D17: =C17-100 -> 111 | G17: =G16-100 -> 4000 | H17: =G17*0.75 -> 3000 | I17: Mr. Fakir 11
B18: Documentation | C18: =C17+1 -> 212 | D18: =C18-100 -> 112 | G18: =G17-100 -> 3900 | H18: =G18*0.75 -> 2925 | I18: Mr. Fakir 12
B19: Origin Agents fee | C19: =C18+1 -> 213 | D19: =C19-100 -> 113 | G19: =G18-100 -> 3800 | H19: =G19*0.75 -> 2850 | I19: Mr. Fakir 13
B20: Destination Agents Fee | C20: =C19+1 -> 214 | D20: =C20-100 -> 114 | G20: =G19-100 -> 3700 | H20: =G20*0.75 -> 2775 | I20: Mr. Fakir 14
B21: Trucking-Origin | C21: =C20+1 -> 215 | D21: =C21-100 -> 115 | G21: =G20-100 -> 3600 | H21: =G21*0.75 -> 2700 | I21: Mr. Fakir 15
... B44: Courer Fee | C44: =C43+1 -> 238 | D44: =C44-100 -> 138 | G44: =G43-100 -> 1300 | H44: =G44*0.75 -> 975 | I44: Mr. Hamid 08
C45: =C44+1 -> 239 | D45: =C45-100 -> 139 | G45: =G44-100 -> 1200 | H45: =G45*0.75 -> 900 | I45: Mr. Hamid 09
B46: WH-storage | C46: =C45+1 -> 240 | D46: =C46-100 -> 140 | G46: =G45-100 -> 1100 | H46: =G46*0.75 -> 825 | I46: Mr. Hamid 10
B47: WH-handling IN | C47: =C46+1 -> 241 | D47: =C47-100 -> 141 | G47: =G46-100 -> 1000 | H47: =G47*0.75 -> 750 | I47: Mr. Hamid 11
B48: WH-handling OUT | C48: =C47+1 -> 242 | D48: =C48-100 -> 142 | G48: =G47-100 -> 900 | H48: =G48*0.75 -> 675 | I48: Mr. Hamid 12
B49: WH-Loading | C49: =C48+1 -> 243 | D49: =C49-100 -> 143 | G49: =G48-100 -> 800 | H49: =G49*0.75 -> 600 | I49: Mr. Hamid 13
B50: WH-Off loading | C50: =C49+1 -> 244 | D50: =C50-100 -> 144 | G50: =G49-100 -> 700 | H50: =G50*0.75 -> 525 | I50: Mr. Hamid 14
B51: WH-Fork Lift | C51: =C50+1 -> 245 | D51: =C51-100 -> 145 | G51: =G50-100 -> 600 | H51: =G51*0.75 -> 450 | I51: Mr. Hamid 15
B52: WH-Management | C52: =C51+1 -> 246 | D52: =C52-100 -> 146 | G52: =G51-100 -> 500 | H52: =G52*0.75 -> 375 | I52: Mr. Hamid 16
C53: =C52+1 -> 247 | D53: =C53-100 -> 147 | G53: =G52-100 -> 400 | H53: =G53*0.75 -> 300 | I53: Mr. Hamid 17
G54: =G53-100 -> 300 | H54: =G54*0.75 -> 225 | I54: Mr. Hamid 18
G55: =G54-100 -> 200 | H55: =G55*0.75 -> 150 | I55: Mr. Hamid 19
G56: =G55-100 -> 100 | H56: =G56*0.75 -> 75 | I56: Mr. Hamid 20
B57: TOTAL AMOUNT | G57: =SUM(G7:G56) -> 127500 | H57: =G57*0.75 -> 95625

Sheet SUMMARIED-TOTAL
B3: MGL Basic Reports From New Software
B5: SP NAME | C5: ALL | D5: FM WK NO | E5: 1 | F5: TO WEEK NO | G5: 5 | I5: FM MON | J5: 43101 | K5: TO MON | L5: 43101 | M5: Product | N5: Sea Export
B7: SP NAME | D7: NOS | E7: FREIGHT | F7: INLAND | G7: OTHERS | H7: GROSS | I7: FREIGHT | J7: FRT COMM | K7: INLAND | L7: OTHERS | M7: GROSS | N7: GROSS | O7: AVG REV | P7: AVG COST | Q7: AVG MAR | R7: G P RATIO
E8: REVENUE | F8: REVENUE | G8: REVENUE | H8: SALES | I8: COST | J8: 2.5% - [if Y] | K8: COST | L8: COST | M8: COST | N8: PROFIT | O8: PER UNIT | P8: PER UNIT | Q8: PER UNIT | R8: IN %
B9: BHOPAL | D9: ='DETAILED-SP'!D22 -> 19 | E9: ='DETAILED-SP'!E22 -> 38000 | F9: ='DETAILED-SP'!F22 -> 18000 | G9: ='DETAILED-SP'!G22 -> 3800 | H9: =SUM(E9:G9) -> 59800 | I9: ='DETAILED-SP'!I22 -> 30400 | J9: ='DETAILED-SP'!J22 -> -760 | K9: ='DETAILED-SP'!K22 -> 12600 | L9: ='DETAILED-SP'!L22 -> 1900 | M9: =SUM(I9:L9) -> 44140 | N9: =H9-M9 -> 15660 | O9: ='DETAILED-SP'!O22 -> 3147.3684 | P9: ='DETAILED-SP'!P22 -> 2323.1579 | Q9: ='DETAILED-SP'!Q22 -> 824.21053 | R9: =Q9/O9 -> 0.26187291
B10: DELHI | D10: ='DETAILED-SP'!D45 -> 19 | E10: ='DETAILED-SP'!E45 -> 38000 | F10: ='DETAILED-SP'!F45 -> 18000 | G10: ='DETAILED-SP'!G45 -> 3800 | H10: =SUM(E10:G10) -> 59800 | I10: ='DETAILED-SP'!I45 -> 30400 | J10: ='DETAILED-SP'!J45 -> -760 | K10: ='DETAILED-SP'!K45 -> 12600 | L10: ='DETAILED-SP'!L45 -> 1900 | M10: =SUM(I10:L10) -> 44140 | N10: =H10-M10 -> 15660 | O10: =H10/D10 -> 3147.3684 | P10: =M10/D10 -> 2323.1579 | Q10: =N10/D10 -> 824.21053 | R10: =Q10/O10 -> 0.26187291
B11: MUMBAI | D11: ='DETAILED-SP'!D66 -> 19 | E11: ='DETAILED-SP'!E66 -> 38000 | F11: ='DETAILED-SP'!F66 -> 18000 | G11: ='DETAILED-SP'!G66 -> 3800 | H11: =SUM(E11:G11) -> 59800 | I11: ='DETAILED-SP'!I66 -> 30400 | J11: ='DETAILED-SP'!J66 -> -760 | K11: ='DETAILED-SP'!K66 -> 12600 | L11: ='DETAILED-SP'!L66 -> 1900 | M11: =SUM(I11:L11) -> 44140 | N11: =H11-M11 -> 15660 | O11: =H11/D11 -> 3147.3684 | P11: =M11/D11 -> 2323.1579 | Q11: =N11/D11 -> 824.21053 | R11: =Q11/O11 -> 0.26187291
B12: DUBAI | D12: 0 | E12: 0 | F12: 0 | G12: 0 | H12: =SUM(E12:G12) -> 0 | I12: =E12*0.8 -> 0 | J12: =I12*0.025*-1 -> 0 | K12: =F12*0.7 -> 0 | L12: =G12*0.5 -> 0 | M12: =SUM(I12:L12) -> 0 | N12: =H12-M12 -> 0 | O12: =H12/D12 -> #DIV/0! | P12: =M12/D12 -> #DIV/0! | Q12: =N12/D12 -> #DIV/0! | R12: =Q12/O12 -> #DIV/0!
B13: SP004 | D13: 0 | E13: 0 | F13: 0 | G13: 0 | H13: =SUM(E13:G13) -> 0 | I13: =E13*0.8 -> 0 | J13: =I13*0.025*-1 -> 0 | K13: =F13*0.7 -> 0 | L13: =G13*0.5 -> 0 | M13: =SUM(I13:L13) -> 0 | N13: =H13-M13 -> 0 | O13: =H13/D13 -> #DIV/0! | P13: =M13/D13 -> #DIV/0! | Q13: =N13/D13 -> #DIV/0! | R13: =Q13/O13 -> #DIV/0!
B14: SP005 | D14: 0 | E14: 0 | F14: 0 | G14: 0 | H14: =SUM(E14:G14) -> 0 | I14: =E14*0.8 -> 0 | J14: =I14*0.025*-1 -> 0 | K14: =F14*0.7 -> 0 | L14: =G14*0.5 -> 0 | M14: =SUM(I14:L14) -> 0 | N14: =H14-M14 -> 0 | O14: =H14/D14 -> #DIV/0! | P14: =M14/D14 -> #DIV/0! | Q14: =N14/D14 -> #DIV/0! | R14: =Q14/O14 -> #DIV/0!
B15: SP006 | D15: 0 | E15: 0 | F15: 0 | G15: 0 | H15: =SUM(E15:G15) -> 0 | I15: =E15*0.8 -> 0 | J15: =I15*0.025*-1 -> 0 | K15: =F15*0.7 -> 0 | L15: =G15*0.5 -> 0 | M15: =SUM(I15:L15) -> 0 | N15: =H15-M15 -> 0 | O15: =H15/D15 -> #DIV/0! | P15: =M15/D15 -> #DIV/0! | Q15: =N15/D15 -> #DIV/0! | R15: =Q15/O15 -> #DIV/0!
B16: SP007 | D16: 0 | E16: 0 | F16: 0 | G16: 0 | H16: =SUM(E16:G16) -> 0 | I16: =E16*0.8 -> 0 | J16: =I16*0.025*-1 -> 0 | K16: =F16*0.7 -> 0 | L16: =G16*0.5 -> 0 | M16: =SUM(I16:L16) -> 0 | N16: =H16-M16 -> 0 | O16: =H16/D16 -> #DIV/0! | P16: =M16/D16 -> #DIV/0! | Q16: =N16/D16 -> #DIV/0! | R16: =Q16/O16 -> #DIV/0!
B17: SP008 | D17: 0 | E17: 0 | F17: 0 | G17: 0 | H17: =SUM(E17:G17) -> 0 | I17: =E17*0.8 -> 0 | J17: =I17*0.025*-1 -> 0 | K17: =F17*0.7 -> 0 | L17: =G17*0.5 -> 0 | M17: =SUM(I17:L17) -> 0 | N17: =H17-M17 -> 0 | O17: =H17/D17 -> #DIV/0! | P17: =M17/D17 -> #DIV/0! | Q17: =N17/D17 -> #DIV/0! | R17: =Q17/O17 -> #DIV/0!
B18: SP009 | D18: 0 | E18: 0 | F18: 0 | G18: 0 | H18: =SUM(E18:G18) -> 0 | I18: =E18*0.8 -> 0 | J18: =I18*0.025*-1 -> 0 | K18: =F18*0.7 -> 0 | L18: =G18*0.5 -> 0 | M18: =SUM(I18:L18) -> 0 | N18: =H18-M18 -> 0 | O18: =H18/D18 -> #DIV/0! | P18: =M18/D18 -> #DIV/0! | Q18: =N18/D18 -> #DIV/0! | R18: =Q18/O18 -> #DIV/0!
B19: SP010 | D19: 0 | E19: 0 | F19: 0 | G19: 0 | H19: =SUM(E19:G19) -> 0 | I19: =E19*0.8 -> 0 | J19: =I19*0.025*-1 -> 0 | K19: =F19*0.7 -> 0 | L19: =G19*0.5 -> 0 | M19: =SUM(I19:L19) -> 0 | N19: =H19-M19 -> 0 | O19: =H19/D19 -> #DIV/0! | P19: =M19/D19 -> #DIV/0! | Q19: =N19/D19 -> #DIV/0! | R19: =Q19/O19 -> #DIV/0!
D20: 0 | E20: 0 | F20: 0 | G20: 0 | H20: =SUM(E20:G20) -> 0 | I20: =E20*0.8 -> 0 | J20: =I20*0.025*-1 -> 0 | K20: =F20*0.7 -> 0 | L20: =G20*0.5 -> 0 | M20: =SUM(I20:L20) -> 0 | N20: =H20-M20 -> 0 | O20: =H20/D20 -> #DIV/0! | P20: =M20/D20 -> #DIV/0! | Q20: =N20/D20 -> #DIV/0! | R20: =Q20/O20 -> #DIV/0!
D21: 0 | E21: 0 | F21: 0 | G21: 0 | H21: =SUM(E21:G21) -> 0 | I21: =E21*0.8 -> 0 | J21: =I21*0.025*-1 -> 0 | K21: =F21*0.7 -> 0 | L21: =G21*0.5 -> 0 | M21: =SUM(I21:L21) -> 0 | N21: =H21-M21 -> 0 | O21: =H21/D21 -> #DIV/0! | P21: =M21/D21 -> #DIV/0! | Q21: =N21/D21 -> #DIV/0! | R21: =Q21/O21 -> #DIV/0!
D22: 0 | E22: 0 | F22: 0 | G22: 0 | H22: =SUM(E22:G22) -> 0 | I22: =E22*0.8 -> 0 | J22: =I22*0.025*-1 -> 0 | K22: =F22*0.7 -> 0 | L22: =G22*0.5 -> 0 | M22: =SUM(I22:L22) -> 0 | N22: =H22-M22 -> 0 | O22: =H22/D22 -> #DIV/0! | P22: =M22/D22 -> #DIV/0! | Q22: =N22/D22 -> #DIV/0! | R22: =Q22/O22 -> #DIV/0!
B23: TOTALS | C23: =C5 -> ALL | D23: =SUM(D9:D22) -> 57 | E23: =SUM(E9:E22) -> 114000 | F23: =SUM(F9:F22) -> 54000 | G23: =SUM(G9:G22) -> 11400 | H23: =SUM(H9:H22) -> 179400 | I23: =SUM(I9:I22) -> 91200 | J23: =SUM(J9:J22) -> -2280 | K23: =SUM(K9:K22) -> 37800 | ... N23: =SUM(N9:N22) -> 46980 | O23: =H23/D23 -> 3147.3684 | P23: =M23/D23 -> 2323.1579 | Q23: =N23/D23 -> 824.21053 | R23: =Q23/O23 -> 0.26187291

Sheet SP-COMM
B2: MGL Basic Reports From New Software | H2: SP COMMISSION REPORT
B4: SP NAME | C4: BHOPAL | D4: FM WK NO | E4: 1 | F4: TO WEEK NO | G4: 5 | I4: FM MON | J4: 43101 | K4: TO MON | L4: 43101 | M4: Product | N4: Sea Export
B5: CLASSIFICATION | D5: MARGIN | E5: PROV 5% | F5: NET MARGIN | G5: TTL COM % | H5: TTL COMM | I5: % SP-BH | J5: % SP XX | K5: COMM SP-BH | L5: COMM SP-XX | M5: RECON
B6: BUSINESS TYPE | C6: AA | D6: ='SUMMARIED-TOTAL'!N9/8 -> 1957.5 | E6: =D6*0.05 -> 97.875 | F6: =D6-E6 -> 1859.625 | G6: 0.2 | H6: =F6*G6 -> 371.925 | I6: 1 | J6: 0 | K6: =H6*I6 -> 371.925 | L6: =H6*J6 -> 0 | M6: =SUM(K6:L6) -> 371.925
B7: BUSINESS TYPE | C7: BB | D7: =D6 -> 1957.5 | E7: =D7*0.05 -> 97.875 | F7: =D7-E7 -> 1859.625 | G7: 0.2 | H7: =F7*G7 -> 371.925 | I7: 1 | J7: 0 | K7: =H7*I7 -> 371.925 | L7: =H7*J7 -> 0 | M7: =SUM(K7:L7) -> 371.925
B8: BUSINESS TYPE | C8: CC | D8: =D7 -> 1957.5 | E8: =D8*0.05 -> 97.875 | F8: =D8-E8 -> 1859.625 | G8: 0.2 | H8: =F8*G8 -> 371.925 | I8: 1 | J8: 0 | K8: =H8*I8 -> 371.925 | L8: =H8*J8 -> 0 | M8: =SUM(K8:L8) -> 371.925
B9: BUSINESS TYPE | C9: DD | D9: =D8 -> 1957.5 | E9: =D9*0.05 -> 97.875 | F9: =D9-E9 -> 1859.625 | G9: 0.2 | H9: =F9*G9 -> 371.925 | I9: 1 | J9: 0 | K9: =H9*I9 -> 371.925 | L9: =H9*J9 -> 0 | M9: =SUM(K9:L9) -> 371.925
B10: BUSINESS TYPE | C10: EE | D10: =D9 -> 1957.5 | E10: =D10*0.05 -> 97.875 | F10: =D10-E10 -> 1859.625 | G10: 0.2 | H10: =F10*G10 -> 371.925 | I10: 1 | J10: 0 | K10: =H10*I10 -> 371.925 | L10: =H10*J10 -> 0 | M10: =SUM(K10:L10) -> 371.925
B11: BUSINESS TYPE | C11: FF | D11: =D10 -> 1957.5 | E11: =D11*0.05 -> 97.875 | F11: =D11-E11 -> 1859.625 | G11: 0.2 | H11: =F11*G11 -> 371.925 | I11: 1 | J11: 0 | K11: =H11*I11 -> 371.925 | L11: =H11*J11 -> 0 | M11: =SUM(K11:L11) -> 371.925
B12: BUSINESS TYPE | C12: GG | D12: =D11 -> 1957.5 | E12: =D12*0.05 -> 97.875 | F12: =D12-E12 -> 1859.625 | G12: 0.3 | H12: =F12*G12 -> 557.8875 | I12: 0.7 | J12: 0.3 | K12: =H12*I12 -> 390.52125 | L12: =H12*J12 -> 167.36625 | M12: =SUM(K12:L12) -> 557.8875
B13: BUSINESS TYPE | C13: HH | D13: =D12 -> 1957.5 | E13: =D13*0.05 -> 97.875 | F13: =D13-E13 -> 1859.625 | G13: 0.4 | H13: =F13*G13 -> 743.85 | I13: 0.5 | J13: 0.5 | K13: =H13*I13 -> 371.925 | L13: =H13*J13 -> 371.925 | M13: =SUM(K13:L13) -> 743.85
B20: TOTAL | C20: =C4 -> BHOPAL | D20: =SUM(D6:D19) -> 15660 | E20: =D20*0.05 -> 783 | F20: =D20-E20 -> 14877 | H20: =SUM(H6:H13) -> 3533.2875 | K20: =SUM(K6:K19) -> 2993.9963 | L20: =SUM(L6:L19) -> 539.29125 | M20: =SUM(M6:M19) -> 3533.2875

Sheet SP-COMM-SUMMARY
B2: MGL Basic Reports From New Software | E2: SP COMMISSION REPORT | G2: SUMMARISED
B4: SP NAME | C4: ALL | D4: FM WK NO | E4: 1 | F4: TO WEEK NO | G4: 5 | I4: FM MON | J4: 43101 | K4: TO MON | L4: 43101 | M4: Product | N4: Sea Export
B5: CLASSIFICATION | D5: MARGIN | E5: PROV E&O 5% | F5: NET MARGIN | G5: COMM EARNED | H5: COMM PAID | I5: NET POSITION | J5: =E5 -> PROV E&O 5% | K5: E&O CHGS | L5: PROV BAL
B6: BHOPAL | D6: 20000 | E6: =D6*0.05 -> 1000 | F6: =D6-E6 -> 19000 | G6: 4275 | H6: 4000 | I6: =G6-H6 -> 275 | J6: =E6 -> 1000 | K6: 700 | L6: =J6-K6 -> 300
B7: DELHI | D7: =D6 -> 20000 | E7: =D7*0.05 -> 1000 | F7: =D7-E7 -> 19000 | G7: 4275 | H7: 4000 | I7: =G7-H7 -> 275 | J7: =E7 -> 1000 | K7: =K6+100 -> 800 | L7: =J7-K7 -> 200
B8: MUMBAI | D8: =D7 -> 20000 | E8: =D8*0.05 -> 1000 | F8: =D8-E8 -> 19000 | G8: 4275 | H8: 4000 | I8: =G8-H8 -> 275 | J8: =E8 -> 1000 | K8: =K7+100 -> 900 | L8: =J8-K8 -> 100
B9: DUBAI | D9: =D8 -> 20000 | E9: =D9*0.05 -> 1000 | F9: =D9-E9 -> 19000 | G9: 4275 | H9: 4000 | I9: =G9-H9 -> 275 | J9: =E9 -> 1000 | K9: =K8+100 -> 1000 | L9: =J9-K9 -> 0
B10: SP004 | D10: =D9 -> 20000 | E10: =D10*0.05 -> 1000 | F10: =D10-E10 -> 19000 | G10: 4275 | H10: 4000 | I10: =G10-H10 -> 275 | J10: =E10 -> 1000 | K10: =K9+100 -> 1100 | L10: =J10-K10 -> -100
B11: SP005 | D11: =D10 -> 20000 | E11: =D11*0.05 -> 1000 | F11: =D11-E11 -> 19000 | G11: 4275 | H11: 4000 | I11: =G11-H11 -> 275 | J11: =E11 -> 1000 | K11: =K10+100 -> 1200 | L11: =J11-K11 -> -200
B12: SP006 | D12: =D11 -> 20000 | E12: =D12*0.05 -> 1000 | F12: =D12-E12 -> 19000 | G12: 4275 | H12: 4000 | I12: =G12-H12 -> 275 | J12: =E12 -> 1000 | K12: =K11+100 -> 1300 | L12: =J12-K12 -> -300
B13: SP007 | D13: =D12 -> 20000 | E13: =D13*0.05 -> 1000 | F13: =D13-E13 -> 19000 | G13: 4275 | H13: 4000 | I13: =G13-H13 -> 275 | J13: =E13 -> 1000 | K13: =K12+100 -> 1400 | L13: =J13-K13 -> -400
B14: SP008 | I14: 0 | J14: =E14 -> 0
B15: SP009 | I15: =G15-H15 -> 0 | J15: =E15 -> 0
B16: SP010 | I16: =G16-H16 -> 0 | J16: =E16 -> 0
I17: =G17-H17 -> 0
I18: =G18-H18 -> 0
I19: =G19-H19 -> 0
B20: TOTAL | C20: =C4 -> ALL | D20: =SUM(D6:D19) -> 160000 | E20: =D20*0.05 -> 8000 | F20: =SUM(F6:F19) -> 152000 | G20: =SUM(G6:G19) -> 34200 | H20: =SUM(H6:H19) -> 32000 | I20: =SUM(I6:I19) -> 2200 | J20: =SUM(J6:J19) -> 8000 | K20: =SUM(K6:K19) -> 8400 | L20: =SUM(L6:L19) -> -400 | M20: =SUM(M6:M19) -> 0
